data/test/input/20190903/test.csv
Date,Timestamp,OrderNumber,EventType,Ticker,Price,Quantity,MPID,Exchange
20160901,04:00:00.039,7689,ADD BID,ABEO,3.2,563,ABC,ARCA
20160901,04:00:00.039,10389,ADD BID,ABEO,0.4,10,EFG,ARCA
20160901,04:00:00.039,10398,ADD ASK,ABEO,4.75,1,HIJ,ARCA
20160901,04:00:00.039,10407,ADD ASK,ABEO,5.4,600,KLM,ARCA
20160901,04:00:00.039,10416,ADD ASK,ABEO,10.11,4700,NOP,ARCA
20160901,04:00:21.799,7689,DELETE BID,ABEO,0.0,563,QRS,ARCA
20160901,04:00:00.039,109,ADD BID,ABEO,0.5,10000,TUV,ARCA
20160901,04:02:40.405,10389,DELETE BID,ABEO,0.0,10,WXY,ARCA
